<?xml version="1.0" ?>
<!-- =================================================================================== -->
<!-- |    This document was autogenerated by xacro from src/rc_car/launch/ego_racecar.xacro | -->
<!-- |    EDITING THIS FILE BY HAND IS NOT RECOMMENDED                                 | -->
<!-- =================================================================================== -->
<!-- A simple model of the racecar for rviz -->
<robot name="racecar">
  <!-- Specify some standard inertial calculations https://en.wikipedia.org/wiki/List_of_moments_of_inertia -->
  <!-- These make use of xacro's mathematical functionality -->
  <gazebo>
    <plugin filename="libgazebo_ros_ackermann_drive.so" name="gazebo_ros_ackermann_drive">
      <!-- wheels -->
      <front_left_joint>base_to_front_left_hinge</front_left_joint>
      <front_right_joint>base_to_front_right_hinge</front_right_joint>
      <rear_left_joint>base_to_back_left_wheel</rear_left_joint>
      <rear_right_joint>base_to_back_right_wheel</rear_right_joint>
      <left_steering_joint>front_left_hinge_to_wheel</left_steering_joint>
      <right_steering_joint>front_right_hinge_to_wheel</right_steering_joint>
      <!-- <steering_wheel_joint>steering_joint</steering_wheel_joint> -->
      <!-- Max absolute steer angle for tyre in radians-->
      <!-- Any cmd_vel angular z greater than this would be capped -->
      <max_steer>0.6458</max_steer>
      <!-- Max absolute steering angle of steering wheel -->
      <max_steering_angle>7.85</max_steering_angle>
      <!-- Max absolute linear speed in m/s -->
      <max_speed>20</max_speed>
      <!-- PID tuning -->
      <left_steering_pid_gain>1500 0 1</left_steering_pid_gain>
      <left_steering_i_range>0 0</left_steering_i_range>
      <right_steering_pid_gain>1500 0 1</right_steering_pid_gain>
      <right_steering_i_range>0 0</right_steering_i_range>
      <linear_velocity_pid_gain>1000 0 1</linear_velocity_pid_gain>
      <linear_velocity_i_range>0 0</linear_velocity_i_range>
      <!-- output -->
      <publish_odom>true</publish_odom>
      <publish_odom_tf>true</publish_odom_tf>
      <publish_wheel_tf>true</publish_wheel_tf>
      <publish_distance>true</publish_distance>
      <odometry_frame>odom_demo</odometry_frame>
      <robot_base_frame>chassis</robot_base_frame>
    </plugin>
  </gazebo>
  <material name="white">
    <color rgba="1 1 1 1"/>
  </material>
  <material name="orange">
    <color rgba="1 0.3 0.1 1"/>
  </material>
  <material name="blue">
    <color rgba="0.2 0.2 1 1"/>
  </material>
  <material name="black">
    <color rgba="0 0 0 1"/>
  </material>
  <!-- BASE -->
  <link name="ego_racecar/base_link">
    <visual>
      <origin xyz="0.1651 0 0.09"/>
      <geometry>
        <box size="0.3302 0.2032 0.1"/>
      </geometry>
    </visual>
    <collision>
      <origin xyz="0.1651 0 0.09"/>
      <geometry>
        <box size="0.3302 0.2032 0.1"/>
      </geometry>
    </collision>
    <inertial>
      <origin rpy="0 0 0" xyz="0.1651 0 0.09"/>
      <mass value="0.5"/>
      <inertia ixx="0.0021370933333333332" ixy="0.0" ixz="0.0" iyy="0.004959668333333334" iyz="0.0" izz="0.006263428333333333"/>
    </inertial>
  </link>
  <gazebo reference="ego_racecar/base_link">
    <material>Gazebo/black</material>
  </gazebo>
  <!-- LASER -->
  <joint name="base_to_laser_model" type="fixed">
    <parent link="ego_racecar/base_link"/>
    <child link="ego_racecar/laser_model"/>
    <origin xyz="0.275 0 0.165"/>
  </joint>
  <link name="ego_racecar/laser_model">
    <visual>
      <geometry>
        <cylinder length="0.05" radius="0.026"/>
      </geometry>
    </visual>
    <collision>
      <geometry>
        <cylinder length="0.05" radius="0.026"/>
      </geometry>
    </collision>
  </link>
  <gazebo reference="ego_racecar/back_right_wheel">
    <material>Gazebo/black</material>
  </gazebo>
  <!-- BACK RIGHT WHEEL -->
  <joint name="base_to_back_right_wheel" type="continuous">
    <parent link="ego_racecar/base_link"/>
    <child link="ego_racecar/back_right_wheel"/>
    <origin rpy="0 0 0" xyz="0 -0.12065 0.0508"/>
    <axis xyz="0 -1 0"/>
  </joint>
  <link name="ego_racecar/back_right_wheel">
    <visual>
      <geometry>
        <cylinder length="0.0381" radius="0.0508"/>
      </geometry>
      <origin rpy="1.5707963267948966 0 0"/>
    </visual>
    <collision>
      <geometry>
        <cylinder length="0.0381" radius="0.0508"/>
      </geometry>
      <origin rpy="1.5707963267948966 0 0"/>
    </collision>
    <inertial>
      <origin rpy="0 0 0" xyz="0 0 0"/>
      <mass value="0.1"/>
      <inertia ixx="7.661274999999999e-05" ixy="0.0" ixz="0.0" iyy="7.661274999999999e-05" iyz="0.0" izz="0.000129032"/>
    </inertial>
  </link>
  <gazebo reference="ego_racecar/back_right_wheel">
    <material>Gazebo/Blue</material>
  </gazebo>
  <!-- BACK LEFT WHEEL -->
  <joint name="base_to_back_left_wheel" type="continuous">
    <parent link="ego_racecar/base_link"/>
    <child link="ego_racecar/back_left_wheel"/>
    <origin rpy="0 0 0" xyz="0 0.12065 0.0508"/>
    <axis xyz="0 1 0"/>
  </joint>
  <link name="ego_racecar/back_left_wheel">
    <visual>
      <geometry>
        <cylinder length="0.0381" radius="0.0508"/>
      </geometry>
      <origin rpy="-1.5707963267948966 0 0"/>
    </visual>
    <collision>
      <geometry>
        <cylinder length="0.0381" radius="0.0508"/>
      </geometry>
      <origin rpy="-1.5707963267948966 0 0"/>
    </collision>
    <inertial>
      <origin rpy="0 0 0" xyz="0 0 0"/>
      <mass value="0.1"/>
      <inertia ixx="7.661274999999999e-05" ixy="0.0" ixz="0.0" iyy="7.661274999999999e-05" iyz="0.0" izz="0.000129032"/>
    </inertial>
  </link>
  <gazebo reference="ego_racecar/back_left_wheel">
    <material>Gazebo/Blue</material>
  </gazebo>
  <!-- FRONT RIGHT HINGE -->
  <joint name="base_to_front_right_hinge" type="continuous">
    <parent link="ego_racecar/base_link"/>
    <child link="ego_racecar/front_right_hinge"/>
    <origin xyz="0.3302 -0.12065 0.0508"/>
    <axis xyz="0 0 -1"/>
  </joint>
  <link name="ego_racecar/front_right_hinge">
    <visual>
      <geometry>
        <cylinder length="0.0381" radius="0.0508"/>
      </geometry>
      <origin rpy="-1.5707963267948966 0 0"/>
    </visual>
    <collision>
      <geometry>
        <cylinder length="0.0381" radius="0.0508"/>
      </geometry>
      <origin rpy="-1.5707963267948966 0 0"/>
    </collision>
    <inertial>
      <origin rpy="0 0 0" xyz="0 0 0"/>
      <mass value="0.1"/>
      <inertia ixx="7.661274999999999e-05" ixy="0.0" ixz="0.0" iyy="7.661274999999999e-05" iyz="0.0" izz="0.000129032"/>
    </inertial>
  </link>
  <gazebo reference="ego_racecar/front_right_hinge">
    <material>Gazebo/Blue</material>
  </gazebo>
  <!-- FRONT RIGHT WHEEL -->
  <joint name="front_right_hinge_to_wheel" type="revolute">
    <parent link="ego_racecar/front_right_hinge"/>
    <child link="ego_racecar/front_right_wheel"/>
    <origin xyz="0 0 0"/>
    <limit effort="100" lower="-1" upper="1" velocity="1"/>
    <dynamics damping="0.0" friction="0.0"/>
  </joint>
  <link name="ego_racecar/front_right_wheel">
    <visual>
      <geometry>
        <cylinder length="0.0381" radius="0.0508"/>
      </geometry>
      <origin rpy="-1.5707963267948966 0 0"/>
    </visual>
    <collision>
      <geometry>
        <cylinder length="0.0381" radius="0.0508"/>
      </geometry>
      <origin rpy="-1.5707963267948966 0 0"/>
    </collision>
    <inertial>
      <origin rpy="0 0 0" xyz="0 0 0"/>
      <mass value="0.1"/>
      <inertia ixx="7.661274999999999e-05" ixy="0.0" ixz="0.0" iyy="7.661274999999999e-05" iyz="0.0" izz="0.000129032"/>
    </inertial>
  </link>
  <gazebo reference="ego_racecar/front_right_wheel">
    <material>Gazebo/Blue</material>
  </gazebo>
  <!-- FRONT LEFT HINGE -->
  <joint name="base_to_front_left_hinge" type="continuous">
    <parent link="ego_racecar/base_link"/>
    <child link="ego_racecar/front_left_hinge"/>
    <origin xyz="0.3302 0.12065 0.0508"/>
    <axis xyz="0 0 1"/>
  </joint>
  <link name="ego_racecar/front_left_hinge">
    <visual>
      <geometry>
        <cylinder length="0.0381" radius="0.0508"/>
      </geometry>
      <origin rpy="1.5707963267948966 0 0"/>
    </visual>
    <collision>
      <geometry>
        <cylinder length="0.0381" radius="0.0508"/>
      </geometry>
      <origin rpy="1.5707963267948966 0 0"/>
    </collision>
    <inertial>
      <origin rpy="0 0 0" xyz="0 0 0"/>
      <mass value="0.1"/>
      <inertia ixx="7.661274999999999e-05" ixy="0.0" ixz="0.0" iyy="7.661274999999999e-05" iyz="0.0" izz="0.000129032"/>
    </inertial>
  </link>
  <gazebo reference="ego_racecar/front_left_hinge">
    <material>Gazebo/Blue</material>
  </gazebo>
  <!-- FRONT LEFT WHEEL -->
  <joint name="front_left_hinge_to_wheel" type="revolute">
    <parent link="ego_racecar/front_left_hinge"/>
    <child link="ego_racecar/front_left_wheel"/>
    <origin xyz="0 0 0"/>
    <limit effort="100" lower="-1" upper="1" velocity="1"/>
    <dynamics damping="0.0" friction="0.0"/>
  </joint>
  <link name="ego_racecar/front_left_wheel">
    <visual>
      <geometry>
        <cylinder length="0.0381" radius="0.0508"/>
      </geometry>
      <origin rpy="1.5707963267948966 0 0"/>
    </visual>
    <collision>
      <geometry>
        <cylinder length="0.0381" radius="0.0508"/>
      </geometry>
      <origin rpy="1.5707963267948966 0 0"/>
    </collision>
    <inertial>
      <origin rpy="0 0 0" xyz="0 0 0"/>
      <mass value="0.1"/>
      <inertia ixx="7.661274999999999e-05" ixy="0.0" ixz="0.0" iyy="7.661274999999999e-05" iyz="0.0" izz="0.000129032"/>
    </inertial>
  </link>
  <gazebo reference="ego_racecar/front_left_wheel">
    <material>Gazebo/Blue</material>
  </gazebo>
</robot>
